2025-04-22 18:11:26,873 ERROR: Exception on /conversion/units [GET] [in /home/runner/workspace/.pythonlibs/lib/python3.11/site-packages/flask/app.py:875]
Traceback (most recent call last):
  File "/home/runner/workspace/.pythonlibs/lib/python3.11/site-packages/flask/app.py", line 1511, in wsgi_app
    response = self.full_dispatch_request()
               ^^^^^^^^^^^^^^^^^^^^^^^^^^^^
  File "/home/runner/workspace/.pythonlibs/lib/python3.11/site-packages/flask/app.py", line 919, in full_dispatch_request
    rv = self.handle_user_exception(e)
         ^^^^^^^^^^^^^^^^^^^^^^^^^^^^^
  File "/home/runner/workspace/.pythonlibs/lib/python3.11/site-packages/flask/app.py", line 917, in full_dispatch_request
    rv = self.dispatch_request()
         ^^^^^^^^^^^^^^^^^^^^^^^
  File "/home/runner/workspace/.pythonlibs/lib/python3.11/site-packages/flask/app.py", line 902, in dispatch_request
    return self.ensure_sync(self.view_functions[rule.endpoint])(**view_args)  # type: ignore[no-any-return]
           ^^^^^^^^^^^^^^^^^^^^^^^^^^^^^^^^^^^^^^^^^^^^^^^^^^^^^^^^^^^^^^^^^
  File "/home/runner/workspace/blueprints/conversion/routes.py", line 38, in manage_units
    from utils.unit_utils import get_global_unit_list
ModuleNotFoundError: No module named 'utils.unit_utils'; 'utils' is not a package
2025-04-22 18:11:27,857 ERROR: Exception on /conversion/units [GET] [in /home/runner/workspace/.pythonlibs/lib/python3.11/site-packages/flask/app.py:875]
Traceback (most recent call last):
  File "/home/runner/workspace/.pythonlibs/lib/python3.11/site-packages/flask/app.py", line 1511, in wsgi_app
    response = self.full_dispatch_request()
               ^^^^^^^^^^^^^^^^^^^^^^^^^^^^
  File "/home/runner/workspace/.pythonlibs/lib/python3.11/site-packages/flask/app.py", line 919, in full_dispatch_request
    rv = self.handle_user_exception(e)
         ^^^^^^^^^^^^^^^^^^^^^^^^^^^^^
  File "/home/runner/workspace/.pythonlibs/lib/python3.11/site-packages/flask/app.py", line 917, in full_dispatch_request
    rv = self.dispatch_request()
         ^^^^^^^^^^^^^^^^^^^^^^^
  File "/home/runner/workspace/.pythonlibs/lib/python3.11/site-packages/flask/app.py", line 902, in dispatch_request
    return self.ensure_sync(self.view_functions[rule.endpoint])(**view_args)  # type: ignore[no-any-return]
           ^^^^^^^^^^^^^^^^^^^^^^^^^^^^^^^^^^^^^^^^^^^^^^^^^^^^^^^^^^^^^^^^^
  File "/home/runner/workspace/blueprints/conversion/routes.py", line 38, in manage_units
    from utils.unit_utils import get_global_unit_list
ModuleNotFoundError: No module named 'utils.unit_utils'; 'utils' is not a package
2025-04-22 18:13:55,339 INFO: BatchTrack startup [in /home/runner/workspace/utils/unit_utils.py:18]
2025-04-22 18:14:20,133 ERROR: Exception on /inventory/ [GET] [in /home/runner/workspace/.pythonlibs/lib/python3.11/site-packages/flask/app.py:875]
Traceback (most recent call last):
  File "/home/runner/workspace/.pythonlibs/lib/python3.11/site-packages/flask/app.py", line 1511, in wsgi_app
    response = self.full_dispatch_request()
               ^^^^^^^^^^^^^^^^^^^^^^^^^^^^
  File "/home/runner/workspace/.pythonlibs/lib/python3.11/site-packages/flask/app.py", line 919, in full_dispatch_request
    rv = self.handle_user_exception(e)
         ^^^^^^^^^^^^^^^^^^^^^^^^^^^^^
  File "/home/runner/workspace/.pythonlibs/lib/python3.11/site-packages/flask/app.py", line 917, in full_dispatch_request
    rv = self.dispatch_request()
         ^^^^^^^^^^^^^^^^^^^^^^^
  File "/home/runner/workspace/.pythonlibs/lib/python3.11/site-packages/flask/app.py", line 902, in dispatch_request
    return self.ensure_sync(self.view_functions[rule.endpoint])(**view_args)  # type: ignore[no-any-return]
           ^^^^^^^^^^^^^^^^^^^^^^^^^^^^^^^^^^^^^^^^^^^^^^^^^^^^^^^^^^^^^^^^^
  File "/home/runner/workspace/.pythonlibs/lib/python3.11/site-packages/flask_login/utils.py", line 290, in decorated_view
    return current_app.ensure_sync(func)(*args, **kwargs)
           ^^^^^^^^^^^^^^^^^^^^^^^^^^^^^^^^^^^^^^^^^^^^^^
  File "/home/runner/workspace/blueprints/inventory/routes.py", line 12, in list_inventory
    return render_template('inventory/list.html', items=items)
           ^^^^^^^^^^^^^^^^^^^^^^^^^^^^^^^^^^^^^^^^^^^^^^^^^^^
  File "/home/runner/workspace/.pythonlibs/lib/python3.11/site-packages/flask/templating.py", line 149, in render_template
    template = app.jinja_env.get_or_select_template(template_name_or_list)
               ^^^^^^^^^^^^^^^^^^^^^^^^^^^^^^^^^^^^^^^^^^^^^^^^^^^^^^^^^^^
  File "/home/runner/workspace/.pythonlibs/lib/python3.11/site-packages/jinja2/environment.py", line 1087, in get_or_select_template
    return self.get_template(template_name_or_list, parent, globals)
           ^^^^^^^^^^^^^^^^^^^^^^^^^^^^^^^^^^^^^^^^^^^^^^^^^^^^^^^^^
  File "/home/runner/workspace/.pythonlibs/lib/python3.11/site-packages/jinja2/environment.py", line 1016, in get_template
    return self._load_template(name, globals)
           ^^^^^^^^^^^^^^^^^^^^^^^^^^^^^^^^^^
  File "/home/runner/workspace/.pythonlibs/lib/python3.11/site-packages/jinja2/environment.py", line 975, in _load_template
    template = self.loader.load(self, name, self.make_globals(globals))
               ^^^^^^^^^^^^^^^^^^^^^^^^^^^^^^^^^^^^^^^^^^^^^^^^^^^^^^^^
  File "/home/runner/workspace/.pythonlibs/lib/python3.11/site-packages/jinja2/loaders.py", line 126, in load
    source, filename, uptodate = self.get_source(environment, name)
                                 ^^^^^^^^^^^^^^^^^^^^^^^^^^^^^^^^^^
  File "/home/runner/workspace/.pythonlibs/lib/python3.11/site-packages/flask/templating.py", line 65, in get_source
    return self._get_source_fast(environment, template)
           ^^^^^^^^^^^^^^^^^^^^^^^^^^^^^^^^^^^^^^^^^^^^
  File "/home/runner/workspace/.pythonlibs/lib/python3.11/site-packages/flask/templating.py", line 99, in _get_source_fast
    raise TemplateNotFound(template)
jinja2.exceptions.TemplateNotFound: inventory/list.html
2025-04-22 18:15:08,476 INFO: BatchTrack startup [in /home/runner/workspace/utils/unit_utils.py:18]
2025-04-22 18:15:11,944 ERROR: Exception on /inventory/ [GET] [in /home/runner/workspace/.pythonlibs/lib/python3.11/site-packages/flask/app.py:875]
Traceback (most recent call last):
  File "/home/runner/workspace/.pythonlibs/lib/python3.11/site-packages/flask/app.py", line 1511, in wsgi_app
    response = self.full_dispatch_request()
               ^^^^^^^^^^^^^^^^^^^^^^^^^^^^
  File "/home/runner/workspace/.pythonlibs/lib/python3.11/site-packages/flask/app.py", line 919, in full_dispatch_request
    rv = self.handle_user_exception(e)
         ^^^^^^^^^^^^^^^^^^^^^^^^^^^^^
  File "/home/runner/workspace/.pythonlibs/lib/python3.11/site-packages/flask/app.py", line 917, in full_dispatch_request
    rv = self.dispatch_request()
         ^^^^^^^^^^^^^^^^^^^^^^^
  File "/home/runner/workspace/.pythonlibs/lib/python3.11/site-packages/flask/app.py", line 902, in dispatch_request
    return self.ensure_sync(self.view_functions[rule.endpoint])(**view_args)  # type: ignore[no-any-return]
           ^^^^^^^^^^^^^^^^^^^^^^^^^^^^^^^^^^^^^^^^^^^^^^^^^^^^^^^^^^^^^^^^^
  File "/home/runner/workspace/.pythonlibs/lib/python3.11/site-packages/flask_login/utils.py", line 290, in decorated_view
    return current_app.ensure_sync(func)(*args, **kwargs)
           ^^^^^^^^^^^^^^^^^^^^^^^^^^^^^^^^^^^^^^^^^^^^^^
  File "/home/runner/workspace/blueprints/inventory/routes.py", line 12, in list_inventory
    return render_template('inventory_list.html', items=items)
           ^^^^^^^^^^^^^^^^^^^^^^^^^^^^^^^^^^^^^^^^^^^^^^^^^^^
  File "/home/runner/workspace/.pythonlibs/lib/python3.11/site-packages/flask/templating.py", line 150, in render_template
    return _render(app, template, context)
           ^^^^^^^^^^^^^^^^^^^^^^^^^^^^^^^
  File "/home/runner/workspace/.pythonlibs/lib/python3.11/site-packages/flask/templating.py", line 131, in _render
    rv = template.render(context)
         ^^^^^^^^^^^^^^^^^^^^^^^^
  File "/home/runner/workspace/.pythonlibs/lib/python3.11/site-packages/jinja2/environment.py", line 1295, in render
    self.environment.handle_exception()
  File "/home/runner/workspace/.pythonlibs/lib/python3.11/site-packages/jinja2/environment.py", line 942, in handle_exception
    raise rewrite_traceback_stack(source=source)
  File "/home/runner/workspace/templates/inventory_list.html", line 2, in top-level template code
    {% extends 'layout.html' %}
    ^^^^^^^^^^^^^^^^^^^^^^^^^
  File "/home/runner/workspace/templates/layout.html", line 58, in top-level template code
    {% block content %}{% endblock %}
    ^^^^^^^^^^^^^^^^^^^^^^^^^
  File "/home/runner/workspace/templates/inventory_list.html", line 29, in block 'content'
    <a href="{{ url_for('inventory.update_inventory', id=item.id) }}" class="btn btn-sm btn-primary">Edit</a>
    ^^^^^^^^^^^^^^^^^^^^^^^^^
  File "/home/runner/workspace/.pythonlibs/lib/python3.11/site-packages/flask/app.py", line 1121, in url_for
    return self.handle_url_build_error(error, endpoint, values)
           ^^^^^^^^^^^^^^^^^^^^^^^^^^^^^^^^^^^^^^^^^^^^^^^^^^^^
  File "/home/runner/workspace/.pythonlibs/lib/python3.11/site-packages/flask/app.py", line 1110, in url_for
    rv = url_adapter.build(  # type: ignore[union-attr]
         ^^^^^^^^^^^^^^^^^^^^^^^^^^^^^^^^^^^^^^^^^^^^^^
  File "/home/runner/workspace/.pythonlibs/lib/python3.11/site-packages/werkzeug/routing/map.py", line 924, in build
    raise BuildError(endpoint, values, method, self)
werkzeug.routing.exceptions.BuildError: Could not build url for endpoint 'inventory.update_inventory' with values ['id']. Did you mean 'inventory.edit_inventory' instead?
2025-04-22 18:16:05,983 INFO: BatchTrack startup [in /home/runner/workspace/utils/unit_utils.py:18]
