2025-05-06 23:48:22,097 ERROR: Exception on /batches/in-progress/35 [GET] [in /home/runner/workspace/.pythonlibs/lib/python3.11/site-packages/flask/app.py:875]
Traceback (most recent call last):
  File "/home/runner/workspace/.pythonlibs/lib/python3.11/site-packages/flask/app.py", line 1511, in wsgi_app
    response = self.full_dispatch_request()
               ^^^^^^^^^^^^^^^^^^^^^^^^^^^^
  File "/home/runner/workspace/.pythonlibs/lib/python3.11/site-packages/flask/app.py", line 919, in full_dispatch_request
    rv = self.handle_user_exception(e)
         ^^^^^^^^^^^^^^^^^^^^^^^^^^^^^
  File "/home/runner/workspace/.pythonlibs/lib/python3.11/site-packages/flask/app.py", line 917, in full_dispatch_request
    rv = self.dispatch_request()
         ^^^^^^^^^^^^^^^^^^^^^^^
  File "/home/runner/workspace/.pythonlibs/lib/python3.11/site-packages/flask/app.py", line 902, in dispatch_request
    return self.ensure_sync(self.view_functions[rule.endpoint])(**view_args)  # type: ignore[no-any-return]
           ^^^^^^^^^^^^^^^^^^^^^^^^^^^^^^^^^^^^^^^^^^^^^^^^^^^^^^^^^^^^^^^^^
  File "/home/runner/workspace/.pythonlibs/lib/python3.11/site-packages/flask_login/utils.py", line 290, in decorated_view
    return current_app.ensure_sync(func)(*args, **kwargs)
           ^^^^^^^^^^^^^^^^^^^^^^^^^^^^^^^^^^^^^^^^^^^^^^
  File "/home/runner/workspace/routes/batch_routes.py", line 214, in view_batch_in_progress
    return render_template('batch_in_progress.html',
           ^^^^^^^^^^^^^^^^^^^^^^^^^^^^^^^^^^^^^^^^^
  File "/home/runner/workspace/.pythonlibs/lib/python3.11/site-packages/flask/templating.py", line 150, in render_template
    return _render(app, template, context)
           ^^^^^^^^^^^^^^^^^^^^^^^^^^^^^^^
  File "/home/runner/workspace/.pythonlibs/lib/python3.11/site-packages/flask/templating.py", line 131, in _render
    rv = template.render(context)
         ^^^^^^^^^^^^^^^^^^^^^^^^
  File "/home/runner/workspace/.pythonlibs/lib/python3.11/site-packages/jinja2/environment.py", line 1295, in render
    self.environment.handle_exception()
  File "/home/runner/workspace/.pythonlibs/lib/python3.11/site-packages/jinja2/environment.py", line 942, in handle_exception
    raise rewrite_traceback_stack(source=source)
  File "/home/runner/workspace/templates/batch_in_progress.html", line 1, in top-level template code
    {% extends 'layout.html' %}
    ^^^^^^^^^^^^^^^^^^^^^^^^^
  File "/home/runner/workspace/templates/layout.html", line 99, in top-level template code
    {% block content %}{% endblock %}
    ^^^^^^^^^^^^^^^^^^^^^^^^^
  File "/home/runner/workspace/templates/batch_in_progress.html", line 108, in block 'content'
    {% set ingredient_total = batch.ingredients|sum(attribute='amount_used', default=0) * batch.ingredients|sum(attribute='ingredient.cost_per_unit', default=0) %}
    ^^^^^^^^^^^^^^^^^^^^^^^^^
  File "/home/runner/workspace/.pythonlibs/lib/python3.11/site-packages/jinja2/async_utils.py", line 48, in wrapper
    return normal_func(*args, **kwargs)
           ^^^^^^^^^^^^^^^^^^^^^^^^^^^^
TypeError: sync_do_sum() got an unexpected keyword argument 'default'
2025-05-06 23:48:37,141 INFO: BatchTrack startup [in /home/runner/workspace/utils/unit_utils.py:17]
2025-05-06 23:53:39,418 INFO: BatchTrack startup [in /home/runner/workspace/utils/unit_utils.py:17]
2025-05-06 23:57:26,872 INFO: BatchTrack startup [in /home/runner/workspace/utils/unit_utils.py:17]
2025-05-06 23:57:43,249 INFO: BatchTrack startup [in /home/runner/workspace/utils/unit_utils.py:17]
2025-05-06 23:58:49,858 INFO: BatchTrack startup [in /home/runner/workspace/utils/unit_utils.py:17]
2025-05-06 23:59:33,146 INFO: BatchTrack startup [in /home/runner/workspace/utils/unit_utils.py:17]
2025-05-07 00:03:32,591 INFO: BatchTrack startup [in /home/runner/workspace/utils/unit_utils.py:17]
2025-05-07 00:10:02,193 INFO: BatchTrack startup [in /home/runner/workspace/utils/unit_utils.py:17]
2025-05-07 00:14:45,686 INFO: BatchTrack startup [in /home/runner/workspace/utils/unit_utils.py:17]
2025-05-07 00:18:13,026 INFO: BatchTrack startup [in /home/runner/workspace/utils/unit_utils.py:17]
2025-05-07 00:19:10,416 INFO: BatchTrack startup [in /home/runner/workspace/utils/unit_utils.py:17]
2025-05-07 19:20:29,129 INFO: BatchTrack startup [in /home/runner/workspace/utils/unit_utils.py:17]
2025-05-07 19:20:56,470 INFO: BatchTrack startup [in /home/runner/workspace/utils/unit_utils.py:17]
2025-05-07 20:22:44,231 INFO: BatchTrack startup [in /home/runner/workspace/utils/unit_utils.py:17]
2025-05-07 20:25:01,649 INFO: BatchTrack startup [in /home/runner/workspace/utils/unit_utils.py:17]
2025-05-07 20:28:41,018 INFO: BatchTrack startup [in /home/runner/workspace/utils/unit_utils.py:17]
2025-05-07 20:31:12,480 INFO: BatchTrack startup [in /home/runner/workspace/utils/unit_utils.py:17]
2025-05-07 20:32:11,465 INFO: BatchTrack startup [in /home/runner/workspace/utils/unit_utils.py:17]
2025-05-07 20:33:28,902 INFO: BatchTrack startup [in /home/runner/workspace/utils/unit_utils.py:17]
2025-05-07 20:38:30,231 INFO: BatchTrack startup [in /home/runner/workspace/utils/unit_utils.py:17]
2025-05-07 20:42:06,185 INFO: BatchTrack startup [in /home/runner/workspace/utils/unit_utils.py:17]
2025-05-07 20:43:36,032 INFO: BatchTrack startup [in /home/runner/workspace/utils/unit_utils.py:17]
2025-05-07 21:08:53,274 INFO: BatchTrack startup [in /home/runner/workspace/utils/unit_utils.py:17]
2025-05-07 21:12:51,423 INFO: BatchTrack startup [in /home/runner/workspace/utils/unit_utils.py:17]
2025-05-07 21:25:55,428 INFO: BatchTrack startup [in /home/runner/workspace/utils/unit_utils.py:17]
2025-05-07 21:33:54,993 INFO: BatchTrack startup [in /home/runner/workspace/utils/unit_utils.py:17]
2025-05-07 21:36:29,023 INFO: BatchTrack startup [in /home/runner/workspace/utils/unit_utils.py:17]
2025-05-07 21:45:05,295 INFO: BatchTrack startup [in /home/runner/workspace/utils/unit_utils.py:17]
2025-05-07 22:03:21,101 INFO: BatchTrack startup [in /home/runner/workspace/utils/unit_utils.py:17]
2025-05-07 22:03:50,067 ERROR: Exception on /batches/ [GET] [in /home/runner/workspace/.pythonlibs/lib/python3.11/site-packages/flask/app.py:875]
Traceback (most recent call last):
  File "/home/runner/workspace/.pythonlibs/lib/python3.11/site-packages/flask/app.py", line 1511, in wsgi_app
    response = self.full_dispatch_request()
               ^^^^^^^^^^^^^^^^^^^^^^^^^^^^
  File "/home/runner/workspace/.pythonlibs/lib/python3.11/site-packages/flask/app.py", line 919, in full_dispatch_request
    rv = self.handle_user_exception(e)
         ^^^^^^^^^^^^^^^^^^^^^^^^^^^^^
  File "/home/runner/workspace/.pythonlibs/lib/python3.11/site-packages/flask/app.py", line 917, in full_dispatch_request
    rv = self.dispatch_request()
         ^^^^^^^^^^^^^^^^^^^^^^^
  File "/home/runner/workspace/.pythonlibs/lib/python3.11/site-packages/flask/app.py", line 902, in dispatch_request
    return self.ensure_sync(self.view_functions[rule.endpoint])(**view_args)  # type: ignore[no-any-return]
           ^^^^^^^^^^^^^^^^^^^^^^^^^^^^^^^^^^^^^^^^^^^^^^^^^^^^^^^^^^^^^^^^^
  File "/home/runner/workspace/.pythonlibs/lib/python3.11/site-packages/flask_login/utils.py", line 290, in decorated_view
    return current_app.ensure_sync(func)(*args, **kwargs)
           ^^^^^^^^^^^^^^^^^^^^^^^^^^^^^^^^^^^^^^^^^^^^^^
  File "/home/runner/workspace/routes/batch_routes.py", line 145, in list_batches
    return render_template('batches_list.html', batches=batches, all_recipes=all_recipes, visible_columns=visible_columns)
           ^^^^^^^^^^^^^^^^^^^^^^^^^^^^^^^^^^^^^^^^^^^^^^^^^^^^^^^^^^^^^^^^^^^^^^^^^^^^^^^^^^^^^^^^^^^^^^^^^^^^^^^^^^^^^^^
  File "/home/runner/workspace/.pythonlibs/lib/python3.11/site-packages/flask/templating.py", line 150, in render_template
    return _render(app, template, context)
           ^^^^^^^^^^^^^^^^^^^^^^^^^^^^^^^
  File "/home/runner/workspace/.pythonlibs/lib/python3.11/site-packages/flask/templating.py", line 131, in _render
    rv = template.render(context)
         ^^^^^^^^^^^^^^^^^^^^^^^^
  File "/home/runner/workspace/.pythonlibs/lib/python3.11/site-packages/jinja2/environment.py", line 1295, in render
    self.environment.handle_exception()
  File "/home/runner/workspace/.pythonlibs/lib/python3.11/site-packages/jinja2/environment.py", line 942, in handle_exception
    raise rewrite_traceback_stack(source=source)
  File "/home/runner/workspace/templates/batches_list.html", line 2, in top-level template code
    {% extends 'layout.html' %}
    ^^^^^^^^^^^^^^^^^^^^^^^^^
  File "/home/runner/workspace/templates/layout.html", line 99, in top-level template code
    {% block content %}{% endblock %}
    ^^^^^^^^^^^^^^^^^^^^^^^^^
  File "/home/runner/workspace/templates/batches_list.html", line 148, in block 'content'
    {% if pagination.has_prev %}
    ^^^^^^^^^^^^^^^^^^^^^^^^^
  File "/home/runner/workspace/.pythonlibs/lib/python3.11/site-packages/jinja2/environment.py", line 490, in getattr
    return getattr(obj, attribute)
           ^^^^^^^^^^^^^^^^^^^^^^^
jinja2.exceptions.UndefinedError: 'pagination' is undefined
2025-05-07 22:04:27,288 INFO: BatchTrack startup [in /home/runner/workspace/utils/unit_utils.py:17]
