2025-05-19 19:04:45,192 INFO: BatchTrack startup [in /home/runner/workspace/utils/unit_utils.py:17]
2025-05-19 19:04:49,067 INFO: BatchTrack startup [in /home/runner/workspace/utils/unit_utils.py:17]
2025-05-19 19:04:54,144 INFO: BatchTrack startup [in /home/runner/workspace/utils/unit_utils.py:17]
2025-05-19 19:04:58,960 INFO: BatchTrack startup [in /home/runner/workspace/utils/unit_utils.py:17]
2025-05-19 19:05:01,065 INFO: BatchTrack startup [in /home/runner/workspace/utils/unit_utils.py:17]
2025-05-19 19:05:03,136 INFO: BatchTrack startup [in /home/runner/workspace/utils/unit_utils.py:17]
2025-05-19 19:06:08,124 INFO: BatchTrack startup [in /home/runner/workspace/utils/unit_utils.py:17]
2025-05-19 19:06:12,710 INFO: BatchTrack startup [in /home/runner/workspace/utils/unit_utils.py:17]
2025-05-19 19:06:38,716 INFO: BatchTrack startup [in /home/runner/workspace/utils/unit_utils.py:17]
2025-05-19 19:07:26,752 INFO: BatchTrack startup [in /home/runner/workspace/utils/unit_utils.py:17]
2025-05-19 19:08:02,405 INFO: BatchTrack startup [in /home/runner/workspace/utils/unit_utils.py:17]
2025-05-19 19:08:06,744 INFO: BatchTrack startup [in /home/runner/workspace/utils/unit_utils.py:17]
2025-05-19 19:10:08,258 INFO: BatchTrack startup [in /home/runner/workspace/utils/unit_utils.py:17]
2025-05-19 19:10:12,903 INFO: BatchTrack startup [in /home/runner/workspace/utils/unit_utils.py:17]
2025-05-19 19:10:43,045 INFO: BatchTrack startup [in /home/runner/workspace/utils/unit_utils.py:17]
2025-05-19 19:11:11,032 INFO: BatchTrack startup [in /home/runner/workspace/utils/unit_utils.py:17]
2025-05-19 19:13:36,317 INFO: BatchTrack startup [in /home/runner/workspace/utils/unit_utils.py:17]
2025-05-19 19:13:41,392 INFO: BatchTrack startup [in /home/runner/workspace/utils/unit_utils.py:17]
2025-05-19 19:30:37,990 INFO: BatchTrack startup [in /home/runner/workspace/utils/unit_utils.py:17]
2025-05-19 19:31:01,849 ERROR: Exception on /inventory/adjust/2 [POST] [in /home/runner/workspace/.pythonlibs/lib/python3.11/site-packages/flask/app.py:875]
Traceback (most recent call last):
  File "/home/runner/workspace/.pythonlibs/lib/python3.11/site-packages/flask/app.py", line 1511, in wsgi_app
    response = self.full_dispatch_request()
               ^^^^^^^^^^^^^^^^^^^^^^^^^^^^
  File "/home/runner/workspace/.pythonlibs/lib/python3.11/site-packages/flask/app.py", line 919, in full_dispatch_request
    rv = self.handle_user_exception(e)
         ^^^^^^^^^^^^^^^^^^^^^^^^^^^^^
  File "/home/runner/workspace/.pythonlibs/lib/python3.11/site-packages/flask/app.py", line 917, in full_dispatch_request
    rv = self.dispatch_request()
         ^^^^^^^^^^^^^^^^^^^^^^^
  File "/home/runner/workspace/.pythonlibs/lib/python3.11/site-packages/flask/app.py", line 902, in dispatch_request
    return self.ensure_sync(self.view_functions[rule.endpoint])(**view_args)  # type: ignore[no-any-return]
           ^^^^^^^^^^^^^^^^^^^^^^^^^^^^^^^^^^^^^^^^^^^^^^^^^^^^^^^^^^^^^^^^^
  File "/home/runner/workspace/.pythonlibs/lib/python3.11/site-packages/flask_login/utils.py", line 290, in decorated_view
    return current_app.ensure_sync(func)(*args, **kwargs)
           ^^^^^^^^^^^^^^^^^^^^^^^^^^^^^^^^^^^^^^^^^^^^^^
  File "/home/runner/workspace/blueprints/inventory/routes.py", line 70, in adjust_inventory
    history = InventoryHistory(
              ^^^^^^^^^^^^^^^^^
  File "<string>", line 4, in __init__
  File "/home/runner/workspace/.pythonlibs/lib/python3.11/site-packages/sqlalchemy/orm/state.py", line 571, in _initialize_instance
    with util.safe_reraise():
  File "/home/runner/workspace/.pythonlibs/lib/python3.11/site-packages/sqlalchemy/util/langhelpers.py", line 146, in __exit__
    raise exc_value.with_traceback(exc_tb)
  File "/home/runner/workspace/.pythonlibs/lib/python3.11/site-packages/sqlalchemy/orm/state.py", line 569, in _initialize_instance
    manager.original_init(*mixed[1:], **kwargs)
  File "/home/runner/workspace/.pythonlibs/lib/python3.11/site-packages/sqlalchemy/orm/decl_base.py", line 2175, in _declarative_constructor
    raise TypeError(
TypeError: 'cost_per_unit' is an invalid keyword argument for InventoryHistory
2025-05-19 19:37:42,615 INFO: BatchTrack startup [in /home/runner/workspace/utils/unit_utils.py:17]
2025-05-19 19:40:54,033 INFO: BatchTrack startup [in /home/runner/workspace/utils/unit_utils.py:17]
2025-05-19 19:41:05,046 ERROR: Exception on /inventory/view/2 [GET] [in /home/runner/workspace/.pythonlibs/lib/python3.11/site-packages/flask/app.py:875]
Traceback (most recent call last):
  File "/home/runner/workspace/.pythonlibs/lib/python3.11/site-packages/flask/app.py", line 1511, in wsgi_app
    response = self.full_dispatch_request()
               ^^^^^^^^^^^^^^^^^^^^^^^^^^^^
  File "/home/runner/workspace/.pythonlibs/lib/python3.11/site-packages/flask/app.py", line 919, in full_dispatch_request
    rv = self.handle_user_exception(e)
         ^^^^^^^^^^^^^^^^^^^^^^^^^^^^^
  File "/home/runner/workspace/.pythonlibs/lib/python3.11/site-packages/flask/app.py", line 917, in full_dispatch_request
    rv = self.dispatch_request()
         ^^^^^^^^^^^^^^^^^^^^^^^
  File "/home/runner/workspace/.pythonlibs/lib/python3.11/site-packages/flask/app.py", line 902, in dispatch_request
    return self.ensure_sync(self.view_functions[rule.endpoint])(**view_args)  # type: ignore[no-any-return]
           ^^^^^^^^^^^^^^^^^^^^^^^^^^^^^^^^^^^^^^^^^^^^^^^^^^^^^^^^^^^^^^^^^
  File "/home/runner/workspace/.pythonlibs/lib/python3.11/site-packages/flask_login/utils.py", line 290, in decorated_view
    return current_app.ensure_sync(func)(*args, **kwargs)
           ^^^^^^^^^^^^^^^^^^^^^^^^^^^^^^^^^^^^^^^^^^^^^^
  File "/home/runner/workspace/blueprints/inventory/routes.py", line 29, in view_inventory
    return render_template('inventory/view.html',
          ^^^^^^^^^^^^^^^^^^^^^^^^^^^^^^^^^^^^^^
  File "/home/runner/workspace/.pythonlibs/lib/python3.11/site-packages/flask/templating.py", line 150, in render_template
    return _render(app, template, context)
           ^^^^^^^^^^^^^^^^^^^^^^^^^^^^^^^
  File "/home/runner/workspace/.pythonlibs/lib/python3.11/site-packages/flask/templating.py", line 131, in _render
    rv = template.render(context)
         ^^^^^^^^^^^^^^^^^^^^^^^^
  File "/home/runner/workspace/.pythonlibs/lib/python3.11/site-packages/jinja2/environment.py", line 1295, in render
    self.environment.handle_exception()
  File "/home/runner/workspace/.pythonlibs/lib/python3.11/site-packages/jinja2/environment.py", line 942, in handle_exception
    raise rewrite_traceback_stack(source=source)
  File "/home/runner/workspace/templates/inventory/view.html", line 1, in top-level template code
    {% extends "layout.html" %}
    ^^^^^^^^^^^^^^^^^^^^^^^^^
  File "/home/runner/workspace/templates/layout.html", line 101, in top-level template code
    {% block content %}{% endblock %}
    ^^^^^^^^^^^^^^^^^^^^^^^^^
  File "/home/runner/workspace/templates/inventory/view.html", line 115, in block 'content'
    <td>{% if entry.created_by %}{{ User.query.get(entry.created_by).username }}{% else %}-{% endif %}</td>
    ^^^^^^^^^^^^^^^^^^^^^^^^^
  File "/home/runner/workspace/.pythonlibs/lib/python3.11/site-packages/jinja2/environment.py", line 490, in getattr
    return getattr(obj, attribute)
           ^^^^^^^^^^^^^^^^^^^^^^^
jinja2.exceptions.UndefinedError: 'User' is undefined
